Workbook

Sheet Index
A1: ="URLs: "&COUNTA($A2:$A4540) &" [missing: "&COUNTBLANK($A2:$A4540)&"]" -> URLs: 4539 [missing: 0] | B1: ="TITLE"&" [missing: "&COUNTBLANK($B2:$B4540)&"]" -> TITLE [missing: 1557] | C1: ="TYPE"&" [missing: "&COUNTBLANK($C2:$C4540)&"]" -> TYPE [missing: 2097] | D1: ="DESCRIPTION"&" [missing: "&COUNTBLANK($D2:$D4540)&"]" -> DESCRIPTION [missing: 1583] | E1: ="AUTHORS"&" [missing: "&COUNTBLANK($E2:$E4540)&"]" -> AUTHORS [missing: 4538] | F1: ="DUPLICATES: " &COUNTIF($F2:$F4540, "True")&" [missing: "&COUNTBLANK($F2:$F4540)&"]" -> DUPLICATES: 0 [missing: 0]
A2: http://ahornung.net/files/pub/2014-vmv-siliconretina-saner.pdf | F2: =COUNTIF($A:$A, $A2)>1 -> FALSE
A3: http://arxiv.org/abs/1803.10106 | F3: =COUNTIF($A:$A, $A3)>1 -> FALSE
A4: http://arxiv.org/abs/2112.01933 | F4: =COUNTIF($A:$A, $A4)>1 -> FALSE
A5: http://arxiv.org/abs/2202.13076 | F5: =COUNTIF($A:$A, $A5)>1 -> FALSE
A6: http://arxiv.org/abs/2203.06145 | B6: Neuromorphic Data Augmentation for Training Spiking Neural Networks | C6: Conference | D6: ECCV 2022 | F6: =COUNTIF($A:$A, $A6)>1 -> FALSE
A7: http://arxiv.org/abs/2203.12247 | B7: Ev-TTA: Test-Time Adaptation for Event-Based Object Recognition | C7: Conference | D7: CVPR 2022 | F7: =COUNTIF($A:$A, $A7)>1 -> FALSE
A8: http://arxiv.org/abs/2206.12455 | B8: Ev-NeRF: Event Based Neural Radiance Field | C8: Conference | D8: WACV 2023 | F8: =COUNTIF($A:$A, $A8)>1 -> FALSE
A9: http://arxiv.org/abs/2207.04007 | B9: Event Collapse in Contrast Maximization Frameworks | C9: Journal | D9: Sensors 2022 | F9: =COUNTIF($A:$A, $A9)>1 -> FALSE
A10: http://arxiv.org/abs/2207.07332 | B10: Stereo Co-capture System for Recording and Tracking Fish with Frame- and Event Cameras | C10: Conference | D10: ICPRW 2022 | F10: =COUNTIF($A:$A, $A10)>1 -> FALSE
A11: http://arxiv.org/abs/2207.11605 | B11: Event-based RGB-D sensing with structured light | C11: Conference | D11: WACV 2023 | F11: =COUNTIF($A:$A, $A11)>1 -> FALSE
A12: http://arxiv.org/abs/2207.13345 | B12: Traffic Sign Detection With Event Cameras and DCNN | C12: Conference | D12: SPA 2022 | F12: =COUNTIF($A:$A, $A12)>1 -> FALSE
A13: http://arxiv.org/abs/2208.01710 | B13: Smart Visual Beacons with Asynchronous Optical Communications using Event Cameras | C13: Conference | D13: IROS 2022 | F13: =COUNTIF($A:$A, $A13)>1 -> FALSE
A14: http://arxiv.org/abs/2208.02253 | B14: LaneSNNs: Spiking Neural Networks for Lane Detection on the Loihi Neuromorphic Processor | C14: Conference | D14: IROS 2022 | F14: =COUNTIF($A:$A, $A14)>1 -> FALSE
A15: http://arxiv.org/abs/2208.08721 | B15: Temporal Up-Sampling for Asynchronous Events | C15: Conference | D15: ICME 2022 | F15: =COUNTIF($A:$A, $A15)>1 -> FALSE
A16: http://arxiv.org/abs/2208.10581 | B16: EBSnoR: Event-Based Snow Removal by Optimal Dwell Time Thresholding | D16: preprint 2022 | F16: =COUNTIF($A:$A, $A16)>1 -> FALSE
A17: http://arxiv.org/abs/2209.04362 | B17: EDeNN: Event Decay Neural Networks for low latency vision | C17: Conference | D17: BMVC 2023 | F17: =COUNTIF($A:$A, $A17)>1 -> FALSE
A18: http://arxiv.org/abs/2209.08323 | B18: RGB-Event Fusion for Moving Object Detection in Autonomous Driving | C18: Conference | D18: ICRA 2023 | F18: =COUNTIF($A:$A, $A18)>1 -> FALSE
A19: http://arxiv.org/abs/2209.08602 | B19: ASAP: Adaptive Transmission Scheme for Online Processing of Event-based Algorithms | C19: Journal | D19: AURO 2022 | F19: =COUNTIF($A:$A, $A19)>1 -> FALSE
A20: http://arxiv.org/abs/2209.12160 | B20: PL-EVIO: Robust Monocular Event-based Visual Inertial Odometry with Point and Line Features | D20: preprint 2022 | F20: =COUNTIF($A:$A, $A20)>1 -> FALSE
A21: http://arxiv.org/abs/2210.01244 | B21: Event-based Temporally Dense Optical Flow Estimation with Sequential Neural Networks | D21: preprint 2022 | F21: =COUNTIF($A:$A, $A21)>1 -> FALSE
A22: http://arxiv.org/abs/2211.00509 | B22: Self-Supervised Intensity-Event Stereo Matching | C22: Journal | D22: JIST 2022 | F22: =COUNTIF($A:$A, $A22)>1 -> FALSE
A23: http://arxiv.org/abs/2305.02888 | B23: Neuromorphic Sensing for Yawn Detection in Driver Drowsiness | D23: preprint 2023 | F23: =COUNTIF($A:$A, $A23)>1 -> FALSE
A24: http://arxiv.org/abs/2407.20446 | B24: MEVDT: Multi-Modal Event-Based Vehicle Detection and Tracking Dataset | C24: Journal | D24: Data in Brief 2024 | F24: =COUNTIF($A:$A, $A24)>1 -> FALSE
A25: http://arxiv.org/abs/2408.07996 | B25: Monte Carlo Path Tracing and Statistical Event Detection for Event Camera Simulation | C25: Conference | D25: ICCP 2024 | F25: =COUNTIF($A:$A, $A25)>1 -> FALSE
A26: http://arxiv.org/abs/2410.06698 | B26: Fourier-based Action Recognition for Wildlife Behavior Quantification with Event Cameras | C26: Journal | D26: AISY 2024 | F26: =COUNTIF($A:$A, $A26)>1 -> FALSE
A27: http://arxiv.org/abs/2411.03303 | B27: Monocular Event-Based Vision for Obstacle Avoidance with a Quadrotor | C27: Conference | D27: CoRL 2024 | F27: =COUNTIF($A:$A, $A27)>1 -> FALSE
A28: http://arxiv.org/abs/2504.04124 | B28: EMF: Event Meta Formers for Event-based Real-time Traffic Object Detection | D28: preprint 2025 | F28: =COUNTIF($A:$A, $A28)>1 -> FALSE
A29: http://arxiv.org/abs/2504.05830 | B29: Human Activity Recognition using RGB-Event based Sensors: A Multi-modal Heat Conduction Model and A Benchmark Dataset | D29: preprint 2025 | F29: =COUNTIF($A:$A, $A29)>1 -> FALSE
A30: http://arxiv.org/abs/2504.12576 | B30: CM3AE: A Unified RGB Frame and Event-Voxel/-Frame Pre-training Framework | D30: preprint 2025 | F30: =COUNTIF($A:$A, $A30)>1 -> FALSE
A31: http://arxiv.org/abs/2505.11165 | B31: Maximizing Asynchronicity in Event-based Neural Networks | D31: preprint 2025 | F31: =COUNTIF($A:$A, $A31)>1 -> FALSE
A32: http://arxiv.org/abs/2506.18443 | B32: Radar and Event Camera Fusion for Agile Robot Ego-Motion Estimation | D32: preprint 2025 | F32: =COUNTIF($A:$A, $A32)>1 -> FALSE
A33: http://arxiv.org/abs/2507.22438 | B33: From Sharp to Blur: Unsupervised Domain Adaptation for 2D Human Pose Estimation Under Extreme Motion Blur Using Event Cameras | C33: Conference | D33: ICCV 2025 | F33: =COUNTIF($A:$A, $A33)>1 -> FALSE
A34: http://arxiv.org/abs/2507.22733 | B34: A Linear N-Point Solver for Structure and Motion from Asynchronous Tracks | D34: preprint 2025 | F34: =COUNTIF($A:$A, $A34)>1 -> FALSE
A35: http://arxiv.org/pdf/2503.23725 | B35: Exploring Temporal Dynamics in Event-based Eye Tracker | C35: Conference | D35: CVPRW 2025 | F35: =COUNTIF($A:$A, $A35)>1 -> FALSE
A36: http://belbachir.info/PDF/icdsc2007.pdf | F36: =COUNTIF($A:$A, $A36)>1 -> FALSE
A37: http://belbachir.info/PDF/itsc2006.pdf | F37: =COUNTIF($A:$A, $A37)>1 -> FALSE
A38: http://bicv.github.io/toc/index.html | F38: =COUNTIF($A:$A, $A38)>1 -> FALSE
A39: http://bmvc2018.org/contents/papers/0280.pdf | B39: Adaptive Time-Slice Block-Matching Optical Flow Algorithm for Dynamic Vision Sensors | C39: Conference | D39: BMVC 2018 | F39: =COUNTIF($A:$A, $A39)>1 -> FALSE
A40: http://bmvc2018.org/contents/papers/0814.pdf | B40: Long-term object tracking with a moving event camera | C40: Conference | D40: BMVC 2018 | F40: =COUNTIF($A:$A, $A40)>1 -> FALSE
...

Sheet Chart Data
A1: Conference Papers | B1: Totals | C1: 2014 | D1: 2015 | E1: 2016 | F1: 2017 | G1: 2018 | H1: 2019 | I1: 2020 | J1: 2021 | K1: 2022 | L1: 2023 | M1: 2024 | N1: 2025
B2: =SUM(B3:B40) -> 977 | C2: =SUM(C3:C40) -> 19 | D2: =SUM(D3:D40) -> 22 | E2: =SUM(E3:E40) -> 22 | F2: =SUM(F3:F40) -> 27 | G2: =SUM(G3:G40) -> 37 | H2: =SUM(H3:H40) -> 61 | I2: =SUM(I3:I40) -> 79 | ... O2: =SUM(O3:O40) -> 1257
A3: CVPR | B3: =SUM(C3:M3) -> 116 | C3: =COUNTIF(Index!$D$2:$D$4903,"CVPR 2014") -> 0 | D3: =COUNTIF(Index!$D$2:$D$4903,"CVPR 2015") -> 1 | E3: =COUNTIF(Index!$D$2:$D$4903,"CVPR 2016") -> 1 | F3: =COUNTIF(Index!$D$2:$D$4903,"CVPR 2017") -> 2 | G3: =COUNTIF(Index!$D$2:$D$4903,"CVPR 2018") -> 4 | H3: =COUNTIF(Index!$D$2:$D$4903,"CVPR 2019") -> 9 | I3: =COUNTIF(Index!$D$2:$D$4903,"CVPR 2020") -> 11 | J3: =COUNTIF(Index!$D$2:$D$4903,"CVPR 2021") -> 10 | K3: =COUNTIF(Index!$D$2:$D$4903,"CVPR 2022") -> 17 | L3: =COUNTIF(Index!$D$2:$D$4903,"CVPR 2023") -> 21 | M3: =COUNTIF(Index!$D$2:$D$4903,"CVPR 2024") -> 40 | N3: =COUNTIF(Index!$D$2:$D$4903,"CVPR 2025") -> 32 | O3: =COUNTIF(Index!$D$2:$D$4903,"CVPR *") -> 148
A4: CVPRW | B4: =SUM(C4:M4) -> 51 | C4: =COUNTIF(Index!$D$2:$D$4903,"CVPRW 2014") -> 2 | D4: =COUNTIF(Index!$D$2:$D$4903,"CVPRW 2015") -> 0 | E4: =COUNTIF(Index!$D$2:$D$4903,"CVPRW 2016") -> 0 | F4: =COUNTIF(Index!$D$2:$D$4903,"CVPRW 2017") -> 1 | G4: =COUNTIF(Index!$D$2:$D$4903,"CVPRW 2018") -> 0 | H4: =COUNTIF(Index!$D$2:$D$4903,"CVPRW 2019") -> 9 | I4: =COUNTIF(Index!$D$2:$D$4903,"CVPRW 2020") -> 1 | J4: =COUNTIF(Index!$D$2:$D$4903,"CVPRW 2021") -> 15 | K4: =COUNTIF(Index!$D$2:$D$4903,"CVPRW 2022") -> 2 | L4: =COUNTIF(Index!$D$2:$D$4903,"CVPRW 2023") -> 7 | M4: =COUNTIF(Index!$D$2:$D$4903,"CVPRW 2024") -> 14 | N4: =COUNTIF(Index!$D$2:$D$4903,"CVPRW 2025") -> 35 | O4: =COUNTIF(Index!$D$2:$D$4903,"CVPRW*") -> 86
A5: ECCV / ICCV | B5: =SUM(C5:M5) -> 117 | C5: =COUNTIF(Index!$D$2:$D$4903,"ECCV 2014") -> 0 | D5: =COUNTIF(Index!$D$2:$D$4903,"ICCV 2015") -> 1 | E5: =COUNTIF(Index!$D$2:$D$4903,"ECCV 2016") -> 1 | F5: =COUNTIF(Index!$D$2:$D$4903,"ICCV 2017") -> 0 | G5: =COUNTIF(Index!$D$2:$D$4903,"ECCV 2018") -> 3 | H5: =COUNTIF(Index!$D$2:$D$4903,"ICCV 2019") -> 4 | I5: =COUNTIF(Index!$D$2:$D$4903,"ECCV 2020") -> 11 | J5: =COUNTIF(Index!$D$2:$D$4903,"ICCV 2021") -> 17 | K5: =COUNTIF(Index!$D$2:$D$4903,"ECCV 2022") -> 14 | L5: =COUNTIF(Index!$D$2:$D$4903,"ICCV 2023") -> 23 | M5: =COUNTIF(Index!$D$2:$D$4903,"ECCV 2024") -> 43 | N5: =COUNTIF(Index!$D$2:$D$4903,"ICCV 2025") -> 37 | O5: =COUNTIF(Index!$D$2:$D$4903,"ECCV *")+COUNTIF(Index!$D$2:$D$4903,"ICCV *") -> 154
A6: ECCVW / ICCVW | B6: =SUM(C6:M6) -> 30 | C6: =COUNTIF(Index!$D$2:$D$4903,"ECCVW 2014") -> 0 | D6: =COUNTIF(Index!$D$2:$D$4903,"ICCVW 2015") -> 0 | E6: =COUNTIF(Index!$D$2:$D$4903,"ECCVW 2016") -> 0 | F6: =COUNTIF(Index!$D$2:$D$4903,"ICCVW 2017") -> 0 | G6: =COUNTIF(Index!$D$2:$D$4903,"ECCVW 2018") -> 1 | H6: =COUNTIF(Index!$D$2:$D$4903,"ICCVW 2019") -> 2 | I6: =COUNTIF(Index!$D$2:$D$4903,"ECCVW 2020") -> 0 | J6: =COUNTIF(Index!$D$2:$D$4903,"ICCVW 2021") -> 1 | K6: =COUNTIF(Index!$D$2:$D$4903,"ECCVW 2022") -> 3 | L6: =COUNTIF(Index!$D$2:$D$4903,"ICCVW 2023") -> 0 | M6: =COUNTIF(Index!$D$2:$D$4903,"ECCVW 2024") -> 23 | N6: =COUNTIF(Index!$D$2:$D$4903,"ICCVW 2025") -> 17 | O6: =COUNTIF(Index!$D$2:$D$4903,"ECCVW *")+COUNTIF(Index!$D$2:$D$4903,"ICCVW *") -> 47
A7: BMVC | B7: =SUM(C7:M7) -> 21 | C7: =COUNTIF(Index!$D$2:$D$4903,"BMVC 2014") -> 1 | D7: =COUNTIF(Index!$D$2:$D$4903,"BMVC 2015") -> 0 | E7: =COUNTIF(Index!$D$2:$D$4903,"BMVC 2016") -> 2 | F7: =COUNTIF(Index!$D$2:$D$4903,"BMVC 2017") -> 4 | G7: =COUNTIF(Index!$D$2:$D$4903,"BMVC 2018") -> 3 | H7: =COUNTIF(Index!$D$2:$D$4903,"BMVC 2019") -> 1 | I7: =COUNTIF(Index!$D$2:$D$4903,"BMVC 2020") -> 2 | J7: =COUNTIF(Index!$D$2:$D$4903,"BMVC 2021") -> 2 | K7: =COUNTIF(Index!$D$2:$D$4903,"BMVC 2022") -> 5 | L7: =COUNTIF(Index!$D$2:$D$4903,"BMVC 2023") -> 1 | M7: =COUNTIF(Index!$D$2:$D$4903,"BMVC 2024") -> 0 | N7: =COUNTIF(Index!$D$2:$D$4903,"BMVC 2025") -> 3 | O7: =COUNTIF(Index!$D$2:$D$4903,"BMVC *") -> 24
A8: WACV + W | B8: =SUM(C8:M8) -> 22 | E8: =COUNTIF(Index!$D$2:$D$4903,"WACV 2016")+COUNTIF(Index!$D$2:$D$4903,"WACVW 2016") -> 1 | F8: =COUNTIF(Index!$D$2:$D$4903,"WACV 2017")+COUNTIF(Index!$D$2:$D$4903,"WACVW 2017") -> 0 | G8: =COUNTIF(Index!$D$2:$D$4903,"WACV 2018")+COUNTIF(Index!$D$2:$D$4903,"WACVW 2018") -> 0 | H8: =COUNTIF(Index!$D$2:$D$4903,"WACV 2019")+COUNTIF(Index!$D$2:$D$4903,"WACVW 2019") -> 2 | I8: =COUNTIF(Index!$D$2:$D$4903,"WACV 2020")+COUNTIF(Index!$D$2:$D$4903,"WACVW 2020") -> 5 | J8: =COUNTIF(Index!$D$2:$D$4903,"WACV 2021")+COUNTIF(Index!$D$2:$D$4903,"WACVW 2021") -> 0 | K8: =COUNTIF(Index!$D$2:$D$4903,"WACV 2022")+COUNTIF(Index!$D$2:$D$4903,"WACVW 2022") -> 2 | L8: =COUNTIF(Index!$D$2:$D$4903,"WACV 2023")+COUNTIF(Index!$D$2:$D$4903,"WACVW 2023") -> 3 | M8: =COUNTIF(Index!$D$2:$D$4903,"WACV 2024")+COUNTIF(Index!$D$2:$D$4903,"WACVW 2024") -> 9 | N8: =COUNTIF(Index!$D$2:$D$4903,"WACV 2025")+COUNTIF(Index!$D$2:$D$4903,"WACVW 2025") -> 12 | O8: =COUNTIF(Index!$D$2:$D$4903,"WACV *")+COUNTIF(Index!$D$2:$D$4903,"WACVW *") -> 36
A9: 3DV | B9: =SUM(C9:M9) -> 12 | G9: =COUNTIF(Index!$D$2:$D$4903,"3DV 2018") -> 2 | H9: =COUNTIF(Index!$D$2:$D$4903,"3DV 2019") -> 1 | I9: =COUNTIF(Index!$D$2:$D$4903,"3DV 2020") -> 1 | J9: =COUNTIF(Index!$D$2:$D$4903,"3DV 2021") -> 3 | K9: =COUNTIF(Index!$D$2:$D$4903,"3DV 2022") -> 1 | L9: =COUNTIF(Index!$D$2:$D$4903,"3DV 2023") -> 0 | M9: =COUNTIF(Index!$D$2:$D$4903,"3DV 2024") -> 4 | N9: =COUNTIF(Index!$D$2:$D$4903,"3DV 2025") -> 1 | O9: =COUNTIF(Index!$D$2:$D$4903,"3DV *") -> 13
A10: ICCP | B10: =SUM(C10:M10) -> 5 | D10: =COUNTIF(Index!$D$2:$D$4903,"ICCP 2015") -> 1 | E10: =COUNTIF(Index!$D$2:$D$4903,"ICCP 2016") -> 0 | F10: =COUNTIF(Index!$D$2:$D$4903,"ICCP 2017") -> 1 | G10: =COUNTIF(Index!$D$2:$D$4903,"ICCP 2018") -> 0 | H10: =COUNTIF(Index!$D$2:$D$4903,"ICCP 2019") -> 0 | I10: =COUNTIF(Index!$D$2:$D$4903,"ICCP 2020") -> 1 | J10: =COUNTIF(Index!$D$2:$D$4903,"ICCP 2021") -> 1 | K10: =COUNTIF(Index!$D$2:$D$4903,"ICCP 2022") -> 0 | L10: =COUNTIF(Index!$D$2:$D$4903,"ICCP 2023") -> 0 | M10: =COUNTIF(Index!$D$2:$D$4903,"ICCP 2024") -> 1 | N10: =COUNTIF(Index!$D$2:$D$4903,"ICCP 2025") -> 0 | O10: =COUNTIF(Index!$D$2:$D$4903,"ICCP *") -> 5
A11: ICIP | B11: =SUM(C11:M11) -> 26 | C11: =COUNTIF(Index!$D$2:$D$4903,"ICIP 2014") -> 2 | D11: =COUNTIF(Index!$D$2:$D$4903,"ICIP 2015") -> 1 | E11: =COUNTIF(Index!$D$2:$D$4903,"ICIP 2016") -> 2 | F11: =COUNTIF(Index!$D$2:$D$4903,"ICIP 2017") -> 0 | G11: =COUNTIF(Index!$D$2:$D$4903,"ICIP 2018") -> 0 | H11: =COUNTIF(Index!$D$2:$D$4903,"ICIP 2019") -> 0 | I11: =COUNTIF(Index!$D$2:$D$4903,"ICIP 2020") -> 3 | J11: =COUNTIF(Index!$D$2:$D$4903,"ICIP 2021") -> 3 | K11: =COUNTIF(Index!$D$2:$D$4903,"ICIP 2022") -> 6 | L11: =COUNTIF(Index!$D$2:$D$4903,"ICIP 2023") -> 4 | M11: =COUNTIF(Index!$D$2:$D$4903,"ICIP 2024") -> 5 | N11: =COUNTIF(Index!$D$2:$D$4903,"ICIP 2025") -> 6 | O11: =COUNTIF(Index!$D$2:$D$4903,"ICIP *") -> 32
A12: ICASSP | B12: =SUM(C12:M12) -> 7 | H12: =COUNTIF(Index!$D$2:$D$4903,"ICASSP 2019") -> 1 | I12: =COUNTIF(Index!$D$2:$D$4903,"ICASSP 2020") -> 1 | J12: =COUNTIF(Index!$D$2:$D$4903,"ICASSP 2021") -> 0 | K12: =COUNTIF(Index!$D$2:$D$4903,"ICASSP 2022") -> 1 | L12: =COUNTIF(Index!$D$2:$D$4903,"ICASSP 2023") -> 2 | M12: =COUNTIF(Index!$D$2:$D$4903,"ICASSP 2024") -> 2 | N12: =COUNTIF(Index!$D$2:$D$4903,"ICASSP 2025") -> 8 | O12: =COUNTIF(Index!$D$2:$D$4903,"ICASSP *") -> 15
A13: IJCAI | B13: =SUM(C13:M13) -> 4 | J13: =COUNTIF(Index!$D$2:$D$4903,"IJCAI 2021") -> 2 | K13: =COUNTIF(Index!$D$2:$D$4903,"IJCAI 2022") -> 0 | L13: =COUNTIF(Index!$D$2:$D$4903,"IJCAI 2023") -> 0 | M13: =COUNTIF(Index!$D$2:$D$4903,"IJCAI 2024") -> 2 | N13: =COUNTIF(Index!$D$2:$D$4903,"IJCAI 2025") -> 1 | O13: =COUNTIF(Index!$D$2:$D$4903,"IJCAI *") -> 5
A14: IJCNN | B14: =SUM(C14:M14) -> 22 | J14: =COUNTIF(Index!$D$2:$D$4903,"IJCNN 2021") -> 3 | K14: =COUNTIF(Index!$D$2:$D$4903,"IJCNN 2022") -> 6 | L14: =COUNTIF(Index!$D$2:$D$4903,"IJCNN 2023") -> 2 | M14: =COUNTIF(Index!$D$2:$D$4903,"IJCNN 2024") -> 11 | N14: =COUNTIF(Index!$D$2:$D$4903,"IJCNN 2025") -> 9 | O14: =COUNTIF(Index!$D$2:$D$4903,"IJCNN *") -> 31
A15: NeurIPS | B15: =SUM(C15:M15) -> 19 | G15: =COUNTIF(Index!$D$2:$D$4903,"Neurips 2018") -> 1 | H15: =COUNTIF(Index!$D$2:$D$4903,"Neurips 2019") -> 0 | I15: =COUNTIF(Index!$D$2:$D$4903,"Neurips 2020") -> 1 | J15: =COUNTIF(Index!$D$2:$D$4903,"Neurips 2021") -> 2 | K15: =COUNTIF(Index!$D$2:$D$4903,"Neurips 2022") -> 2 | L15: =COUNTIF(Index!$D$2:$D$4903,"Neurips 2023") -> 4 | M15: =COUNTIF(Index!$D$2:$D$4903,"Neurips 2024") -> 9 | N15: =COUNTIF(Index!$D$2:$D$4903,"Neurips 2025") -> 23 | O15: =COUNTIF(Index!$D$2:$D$4903,"Neurips 20*") -> 42
A16: NeurIPS-W | B16: =SUM(C16:M16) -> 2 | I16: =COUNTIF(Index!$D$2:$D$4903,"Neurips Workshop 2020") -> 0 | J16: =COUNTIF(Index!$D$2:$D$4903,"Neurips Workshop 2021") -> 0 | K16: =COUNTIF(Index!$D$2:$D$4903,"Neurips Workshop 2022") -> 1 | L16: =COUNTIF(Index!$D$2:$D$4903,"Neurips Workshop 2023") -> 1 | M16: =COUNTIF(Index!$D$2:$D$4903,"Neurips Workshop 2024") -> 0 | N16: =COUNTIF(Index!$D$2:$D$4903,"Neurips Workshop 2025") -> 0 | O16: =COUNTIF(Index!$D$2:$D$4903,"Neurips Workshop 20*") -> 2
A17: AAAI | B17: =SUM(C17:M17) -> 14 | I17: =COUNTIF(Index!$D$2:$D$4903,"AAAI 2020") -> 2 | J17: =COUNTIF(Index!$D$2:$D$4903,"AAAI 2021") -> 1 | K17: =COUNTIF(Index!$D$2:$D$4903,"AAAI 2022") -> 4 | L17: =COUNTIF(Index!$D$2:$D$4903,"AAAI 2023") -> 2 | M17: =COUNTIF(Index!$D$2:$D$4903,"AAAI 2024") -> 5 | N17: =COUNTIF(Index!$D$2:$D$4903,"AAAI 2025") -> 20 | O17: =COUNTIF(Index!$D$2:$D$4903,"AAAI *") -> 35
A18: RSS | B18: =SUM(C18:M18) -> 9 | D18: =COUNTIF(Index!$D$2:$D$4903,"RSS 2015") -> 1 | E18: =COUNTIF(Index!$D$2:$D$4903,"RSS 2016") -> 0 | F18: =COUNTIF(Index!$D$2:$D$4903,"RSS 2017") -> 1 | G18: =COUNTIF(Index!$D$2:$D$4903,"RSS 2018") -> 1 | H18: =COUNTIF(Index!$D$2:$D$4903,"RSS 2019") -> 1 | I18: =COUNTIF(Index!$D$2:$D$4903,"RSS 2020") -> 2 | J18: =COUNTIF(Index!$D$2:$D$4903,"RSS 2021") -> 1 | K18: =COUNTIF(Index!$D$2:$D$4903,"RSS 2022") -> 0 | L18: =COUNTIF(Index!$D$2:$D$4903,"RSS 2023") -> 0 | M18: =COUNTIF(Index!$D$2:$D$4903,"RSS 2024") -> 2 | N18: =COUNTIF(Index!$D$2:$D$4903,"RSS 2025") -> 0 | O18: =COUNTIF(Index!$D$2:$D$4903,"RSS *") -> 9
A19: ICRA + W | B19: =SUM(C19:M19) -> 64 | C19: =COUNTIF(Index!$D$2:$D$4903,"ICRA 2014")+COUNTIF(Index!$D$2:$D$4903,"ICRAW 2014") -> 3 | D19: =COUNTIF(Index!$D$2:$D$4903,"ICRA 2015")+COUNTIF(Index!$D$2:$D$4903,"ICRAW 2015") -> 1 | E19: =COUNTIF(Index!$D$2:$D$4903,"ICRA 2016")+COUNTIF(Index!$D$2:$D$4903,"ICRAW 2016") -> 1 | F19: =COUNTIF(Index!$D$2:$D$4903,"ICRA 2017")+COUNTIF(Index!$D$2:$D$4903,"ICRAW 2017") -> 1 | G19: =COUNTIF(Index!$D$2:$D$4903,"ICRA 2018")+COUNTIF(Index!$D$2:$D$4903,"ICRAW 2018") -> 1 | H19: =COUNTIF(Index!$D$2:$D$4903,"ICRA 2019")+COUNTIF(Index!$D$2:$D$4903,"ICRAW 2019") -> 4 | I19: =COUNTIF(Index!$D$2:$D$4903,"ICRA 2020")+COUNTIF(Index!$D$2:$D$4903,"ICRAW 2020") -> 7 | J19: =COUNTIF(Index!$D$2:$D$4903,"ICRA 2021")+COUNTIF(Index!$D$2:$D$4903,"ICRAW 2021") -> 5 | K19: =COUNTIF(Index!$D$2:$D$4903,"ICRA 2022")+COUNTIF(Index!$D$2:$D$4903,"ICRAW 2022") -> 9 | L19: =COUNTIF(Index!$D$2:$D$4903,"ICRA 2023")+COUNTIF(Index!$D$2:$D$4903,"ICRAW 2023") -> 15 | M19: =COUNTIF(Index!$D$2:$D$4903,"ICRA 2024")+COUNTIF(Index!$D$2:$D$4903,"ICRAW 2024") -> 17 | N19: =COUNTIF(Index!$D$2:$D$4903,"ICRA 2025")+COUNTIF(Index!$D$2:$D$4903,"ICRAW 2025") -> 19 | O19: =COUNTIF(Index!$D$2:$D$4903,"ICRA *")+COUNTIF(Index!$D$2:$D$4903,"ICRAW *") -> 83
A20: IROS + W | B20: =SUM(C20:M20) -> 60 | C20: =COUNTIF(Index!$D$2:$D$4903,"IROS 2014")+COUNTIF(Index!$D$2:$D$4903,"IROSW 2014") -> 1 | D20: =COUNTIF(Index!$D$2:$D$4903,"IROS 2015")+COUNTIF(Index!$D$2:$D$4903,"IROSW 2015") -> 1 | E20: =COUNTIF(Index!$D$2:$D$4903,"IROS 2016")+COUNTIF(Index!$D$2:$D$4903,"IROSW 2016") -> 3 | F20: =COUNTIF(Index!$D$2:$D$4903,"IROS 2017")+COUNTIF(Index!$D$2:$D$4903,"IROSW 2017") -> 1 | G20: =COUNTIF(Index!$D$2:$D$4903,"IROS 2018")+COUNTIF(Index!$D$2:$D$4903,"IROSW 2018") -> 3 | H20: =COUNTIF(Index!$D$2:$D$4903,"IROS 2019")+COUNTIF(Index!$D$2:$D$4903,"IROSW 2019") -> 4 | I20: =COUNTIF(Index!$D$2:$D$4903,"IROS 2020")+COUNTIF(Index!$D$2:$D$4903,"IROSW 2020") -> 5 | J20: =COUNTIF(Index!$D$2:$D$4903,"IROS 2021")+COUNTIF(Index!$D$2:$D$4903,"IROSW 2021") -> 15 | K20: =COUNTIF(Index!$D$2:$D$4903,"IROS 2022")+COUNTIF(Index!$D$2:$D$4903,"IROSW 2022") -> 6 | L20: =COUNTIF(Index!$D$2:$D$4903,"IROS 2023")+COUNTIF(Index!$D$2:$D$4903,"IROSW 2023") -> 7 | M20: =COUNTIF(Index!$D$2:$D$4903,"IROS 2024")+COUNTIF(Index!$D$2:$D$4903,"IROSW 2024") -> 14 | N20: =COUNTIF(Index!$D$2:$D$4903,"IROS 2025")+COUNTIF(Index!$D$2:$D$4903,"IROSW 2025") -> 20 | O20: =COUNTIF(Index!$D$2:$D$4903,"IROS *")+COUNTIF(Index!$D$2:$D$4903,"IROSW *") -> 80
A21: CoRL + W | B21: =SUM(C21:M21) -> 3 | C21: - | D21: - | E21: - | F21: 0 | G21: 1 | H21: 0 | I21: 0 | J21: 0 | K21: 0 | L21: 1 | M21: 1 | O21: =COUNTIF(Index!$D$2:$D$4903,"CoRL *") -> 2
A22: TPAMI | B22: =SUM(C22:M22) -> 43 | D22: =COUNTIF(Index!$D$2:$D$4903,"TPAMI 2015") -> 1 | E22: =COUNTIF(Index!$D$2:$D$4903,"TPAMI 2016") -> 0 | F22: =COUNTIF(Index!$D$2:$D$4903,"TPAMI 2017") -> 1 | G22: =COUNTIF(Index!$D$2:$D$4903,"TPAMI 2018") -> 1 | H22: =COUNTIF(Index!$D$2:$D$4903,"TPAMI 2019") -> 2 | I22: =COUNTIF(Index!$D$2:$D$4903,"TPAMI 2020") -> 4 | J22: =COUNTIF(Index!$D$2:$D$4903,"TPAMI 2021") -> 8 | K22: =COUNTIF(Index!$D$2:$D$4903,"TPAMI 2022") -> 6 | L22: =COUNTIF(Index!$D$2:$D$4903,"TPAMI 2023") -> 9 | M22: =COUNTIF(Index!$D$2:$D$4903,"TPAMI 2024") -> 11 | N22: =COUNTIF(Index!$D$2:$D$4903,"TPAMI 2025") -> 13 | O22: =COUNTIF(Index!$D$2:$D$4903,"TPAMI *") -> 56
A23: IJCV | B23: =SUM(C23:M23) -> 8 | F23: =COUNTIF(Index!$D$2:$D$4903,"IJCV 2017") -> 0 | G23: =COUNTIF(Index!$D$2:$D$4903,"IJCV 2018") -> 2 | H23: =COUNTIF(Index!$D$2:$D$4903,"IJCV 2019") -> 1 | I23: =COUNTIF(Index!$D$2:$D$4903,"IJCV 2020") -> 0 | J23: =COUNTIF(Index!$D$2:$D$4903,"IJCV 2021") -> 0 | K23: =COUNTIF(Index!$D$2:$D$4903,"IJCV 2022") -> 0 | L23: =COUNTIF(Index!$D$2:$D$4903,"IJCV 2023") -> 2 | M23: =COUNTIF(Index!$D$2:$D$4903,"IJCV 2024") -> 3 | N23: =COUNTIF(Index!$D$2:$D$4903,"IJCV 2025") -> 6 | O23: =COUNTIF(Index!$D$2:$D$4903,"IJCV *") -> 16
A24: TIP | B24: =SUM(C24:M24) -> 17 | F24: =COUNTIF(Index!$D$2:$D$4903,"TIP 2017") -> 1 | G24: =COUNTIF(Index!$D$2:$D$4903,"TIP 2018") -> 0 | H24: =COUNTIF(Index!$D$2:$D$4903,"TIP 2019") -> 0 | I24: =COUNTIF(Index!$D$2:$D$4903,"TIP 2020") -> 1 | J24: =COUNTIF(Index!$D$2:$D$4903,"TIP 2021") -> 2 | K24: =COUNTIF(Index!$D$2:$D$4903,"TIP 2022") -> 3 | L24: =COUNTIF(Index!$D$2:$D$4903,"TIP 2023") -> 3 | M24: =COUNTIF(Index!$D$2:$D$4903,"TIP 2024") -> 7 | N24: =COUNTIF(Index!$D$2:$D$4903,"TIP 2025") -> 2 | O24: =COUNTIF(Index!$D$2:$D$4903,"TIP *") -> 19
A25: TCSVT | B25: =SUM(C25:M25) -> 14 | F25: =COUNTIF(Index!$D$2:$D$4903,"TCSVT 2017") -> 0 | G25: =COUNTIF(Index!$D$2:$D$4903,"TCSVT 2018") -> 1 | H25: =COUNTIF(Index!$D$2:$D$4903,"TCSVT 2019") -> 0 | I25: =COUNTIF(Index!$D$2:$D$4903,"TCSVT 2020") -> 0 | J25: =COUNTIF(Index!$D$2:$D$4903,"TCSVT 2021") -> 2 | K25: =COUNTIF(Index!$D$2:$D$4903,"TCSVT 2022") -> 3 | L25: =COUNTIF(Index!$D$2:$D$4903,"TCSVT 2023") -> 2 | M25: =COUNTIF(Index!$D$2:$D$4903,"TCSVT 2024") -> 6 | N25: =COUNTIF(Index!$D$2:$D$4903,"TCSVT 2025") -> 10 | O25: =COUNTIF(Index!$D$2:$D$4903,"TCSVT *") -> 24
A26: TCI | B26: =SUM(C26:M26) -> 5 | F26: =COUNTIF(Index!$D$2:$D$4903,"TCI 2017") -> 0 | G26: =COUNTIF(Index!$D$2:$D$4903,"TCI 2018") -> 0 | H26: =COUNTIF(Index!$D$2:$D$4903,"TCI 2019") -> 2 | I26: =COUNTIF(Index!$D$2:$D$4903,"TCI 2020") -> 1 | J26: =COUNTIF(Index!$D$2:$D$4903,"TCI 2021") -> 0 | K26: =COUNTIF(Index!$D$2:$D$4903,"TCI 2022") -> 1 | L26: =COUNTIF(Index!$D$2:$D$4903,"TCI 2023") -> 1 | M26: =COUNTIF(Index!$D$2:$D$4903,"TCI 2024") -> 0 | N26: =COUNTIF(Index!$D$2:$D$4903,"TCI 2025") -> 0 | O26: =COUNTIF(Index!$D$2:$D$4903,"TCI *") -> 5
A27: TIM | B27: =SUM(C27:M27) -> 7 | F27: =COUNTIF(Index!$D$2:$D$4903,"TIM 2017") -> 0 | G27: =COUNTIF(Index!$D$2:$D$4903,"TIM 2018") -> 0 | H27: =COUNTIF(Index!$D$2:$D$4903,"TIM 2019") -> 0 | I27: =COUNTIF(Index!$D$2:$D$4903,"TIM 2020") -> 0 | J27: =COUNTIF(Index!$D$2:$D$4903,"TIM 2021") -> 1 | K27: =COUNTIF(Index!$D$2:$D$4903,"TIM 2022") -> 1 | L27: =COUNTIF(Index!$D$2:$D$4903,"TIM 2023") -> 2 | M27: =COUNTIF(Index!$D$2:$D$4903,"TIM 2024") -> 3 | N27: =COUNTIF(Index!$D$2:$D$4903,"TIM 2025") -> 4 | O27: =COUNTIF(Index!$D$2:$D$4903,"TIM *") -> 12
A28: TCYB | B28: =SUM(C28:M28) -> 1 | F28: =COUNTIF(Index!$D$2:$D$4903,"TCYB 2017") -> 0 | G28: =COUNTIF(Index!$D$2:$D$4903,"TCYB 2018") -> 0 | H28: =COUNTIF(Index!$D$2:$D$4903,"TCYB 2019") -> 0 | I28: =COUNTIF(Index!$D$2:$D$4903,"TCYB 2020") -> 0 | J28: =COUNTIF(Index!$D$2:$D$4903,"TCYB 2021") -> 0 | K28: =COUNTIF(Index!$D$2:$D$4903,"TCYB 2022") -> 1 | L28: =COUNTIF(Index!$D$2:$D$4903,"TCYB 2023") -> 0 | M28: =COUNTIF(Index!$D$2:$D$4903,"TCYB 2024") -> 0 | N28: =COUNTIF(Index!$D$2:$D$4903,"TCYB 2025") -> 0 | O28: =COUNTIF(Index!$D$2:$D$4903,"TCYB *") -> 1
A29: IEEE SPM special issue | B29: =SUM(C29:M29) -> 8 | H29: 8
A30: RAL | B30: =SUM(C30:M30) -> 59 | F30: =COUNTIF(Index!$D$2:$D$4903,"RAL 2017") -> 2 | G30: =COUNTIF(Index!$D$2:$D$4903,"RAL 2018") -> 3 | H30: =COUNTIF(Index!$D$2:$D$4903,"RAL 2019") -> 2 | I30: =COUNTIF(Index!$D$2:$D$4903,"RAL 2020") -> 5 | J30: =COUNTIF(Index!$D$2:$D$4903,"RAL 2021") -> 11 | K30: =COUNTIF(Index!$D$2:$D$4903,"RAL 2022") -> 11 | L30: =COUNTIF(Index!$D$2:$D$4903,"RAL 2023") -> 10 | M30: =COUNTIF(Index!$D$2:$D$4903,"RAL 2024") -> 15 | N30: =COUNTIF(Index!$D$2:$D$4903,"RAL 2025") -> 21 | O30: =COUNTIF(Index!$D$2:$D$4903,"RAL *") -> 80
A31: TRO | B31: =SUM(C31:M31) -> 8 | E31: =COUNTIF(Index!$D$2:$D$4903,"TRO 2016") -> 0 | F31: =COUNTIF(Index!$D$2:$D$4903,"TRO 2017") -> 0 | G31: =COUNTIF(Index!$D$2:$D$4903,"TRO 2018") -> 1 | H31: =COUNTIF(Index!$D$2:$D$4903,"TRO 2019") -> 0 | I31: =COUNTIF(Index!$D$2:$D$4903,"TRO 2020") -> 0 | J31: =COUNTIF(Index!$D$2:$D$4903,"TRO 2021") -> 1 | K31: =COUNTIF(Index!$D$2:$D$4903,"TRO 2022") -> 0 | L31: =COUNTIF(Index!$D$2:$D$4903,"TRO 2023") -> 1 | M31: =COUNTIF(Index!$D$2:$D$4903,"TRO 2024") -> 5 | N31: =COUNTIF(Index!$D$2:$D$4903,"TRO 2025") -> 2 | O31: =COUNTIF(Index!$D$2:$D$4903,"TRO *") -> 11
A32: IJRR | B32: =SUM(C32:M32) -> 3 | F32: =COUNTIF(Index!$D$2:$D$4903,"IJRR 2017") -> 1 | G32: =COUNTIF(Index!$D$2:$D$4903,"IJRR 2018") -> 0 | H32: =COUNTIF(Index!$D$2:$D$4903,"IJRR 2019") -> 0 | I32: =COUNTIF(Index!$D$2:$D$4903,"IJRR 2020") -> 0 | J32: =COUNTIF(Index!$D$2:$D$4903,"IJRR 2021") -> 0 | K32: =COUNTIF(Index!$D$2:$D$4903,"IJRR 2022") -> 0 | L32: =COUNTIF(Index!$D$2:$D$4903,"IJRR 2023") -> 0 | M32: =COUNTIF(Index!$D$2:$D$4903,"IJRR 2024") -> 2 | N32: =COUNTIF(Index!$D$2:$D$4903,"IJRR 2025") -> 0 | O32: =COUNTIF(Index!$D$2:$D$4903,"IJRR *") -> 3
A33: ISCAS | B33: =SUM(C33:M33) -> 38 | C33: 3 | D33: 7 | E33: 1 | F33: 5 | G33: 3 | H33: 2 | I33: 5 | J33: =COUNTIF(Index!$D$2:$D$4903,"ISCAS 2021") -> 2 | K33: =COUNTIF(Index!$D$2:$D$4903,"ISCAS 2022") -> 3 | L33: =COUNTIF(Index!$D$2:$D$4903,"ISCAS 2023") -> 0 | M33: =COUNTIF(Index!$D$2:$D$4903,"ISCAS 2024") -> 7 | N33: =COUNTIF(Index!$D$2:$D$4903,"ISCAS 2025") -> 8 | O33: =COUNTIF(Index!$D$2:$D$4903,"ISCAS *") -> 20
A34: TNNLS | B34: =SUM(C34:M34) -> 15 | C34: =COUNTIF(Index!$D$2:$D$4903,"TNNLS 2014") -> 2 | D34: =COUNTIF(Index!$D$2:$D$4903,"TNNLS 2015") -> 3 | E34: =COUNTIF(Index!$D$2:$D$4903,"TNNLS 2016") -> 0 | F34: =COUNTIF(Index!$D$2:$D$4903,"TNNLS 2017") -> 2 | G34: =COUNTIF(Index!$D$2:$D$4903,"TNNLS 2018") -> 1 | H34: =COUNTIF(Index!$D$2:$D$4903,"TNNLS 2019") -> 2 | I34: =COUNTIF(Index!$D$2:$D$4903,"TNNLS 2020") -> 0 | J34: =COUNTIF(Index!$D$2:$D$4903,"TNNLS 2021") -> 2 | K34: =COUNTIF(Index!$D$2:$D$4903,"TNNLS 2022") -> 1 | L34: =COUNTIF(Index!$D$2:$D$4903,"TNNLS 2023") -> 1 | M34: =COUNTIF(Index!$D$2:$D$4903,"TNNLS 2024") -> 1 | N34: =COUNTIF(Index!$D$2:$D$4903,"TNNLS 2025") -> 3 | O34: =COUNTIF(Index!$D$2:$D$4903,"TNNLS *") -> 18
A35: FNINS | B35: =SUM(C35:M35) -> 42 | C35: =COUNTIF(Index!$D$2:$D$4903,"FNINS 2014") -> 3 | D35: =COUNTIF(Index!$D$2:$D$4903,"FNINS 2015") -> 2 | E35: =COUNTIF(Index!$D$2:$D$4903,"FNINS 2016") -> 7 | F35: =COUNTIF(Index!$D$2:$D$4903,"FNINS 2017") -> 4 | G35: =COUNTIF(Index!$D$2:$D$4903,"FNINS 2018") -> 4 | H35: =COUNTIF(Index!$D$2:$D$4903,"FNINS 2019") -> 1 | I35: =COUNTIF(Index!$D$2:$D$4903,"FNINS 2020") -> 6 | J35: =COUNTIF(Index!$D$2:$D$4903,"FNINS 2021") -> 2 | K35: =COUNTIF(Index!$D$2:$D$4903,"FNINS 2022") -> 5 | L35: =COUNTIF(Index!$D$2:$D$4903,"FNINS 2023") -> 3 | M35: =COUNTIF(Index!$D$2:$D$4903,"FNINS 2024") -> 5 | N35: =COUNTIF(Index!$D$2:$D$4903,"FNINS 2025") -> 1 | O35: =COUNTIF(Index!$D$2:$D$4903,"FNINS *") -> 44
A36: EBCCSP | B36: =SUM(C36:M36) -> 14 | D36: 2 | E36: 3 | I36: 2 | K36: 7 | O36: =COUNTIF(Index!$D$2:$D$4903,"EBCCSP *") -> 6
A37: IEEE Access | B37: =SUM(C37:M37) -> 33 | G37: 1 | H37: 3 | I37: 2 | J37: =COUNTIF(Index!$D$2:$D$4903,"*Access 2021") -> 5 | K37: =COUNTIF(Index!$D$2:$D$4903,"*Access 2022") -> 7 | L37: =COUNTIF(Index!$D$2:$D$4903,"*Access 2023") -> 9 | M37: =COUNTIF(Index!$D$2:$D$4903,"*Access 2024") -> 6 | N37: =COUNTIF(Index!$D$2:$D$4903,"*Access 2025") -> 6 | O37: =COUNTIF(Index!$D$2:$D$4903,"*Access*") -> 34
A38: Sensors | B38: =SUM(C38:M38) -> 23 | J38: =COUNTIF(Index!$D$2:$D$4903,"Sensors 2021") -> 1 | K38: =COUNTIF(Index!$D$2:$D$4903,"Sensors 2022") -> 7 | L38: =COUNTIF(Index!$D$2:$D$4903,"Sensors 2023") -> 9 | M38: =COUNTIF(Index!$D$2:$D$4903,"Sensors 2024") -> 6 | N38: =COUNTIF(Index!$D$2:$D$4903,"Sensors 2025") -> 14
A39: SPIE | B39: =SUM(C39:M39) -> 33 | J39: =COUNTIF(Index!$D$2:$D$4903,"SPIE 2021") -> 0 | K39: =COUNTIF(Index!$D$2:$D$4903,"SPIE 2022") -> 5 | L39: =COUNTIF(Index!$D$2:$D$4903,"SPIE 2023") -> 14 | M39: =COUNTIF(Index!$D$2:$D$4903,"SPIE 2024") -> 14 | N39: =COUNTIF(Index!$D$2:$D$4903,"SPIE 2025") -> 19 | O39: =COUNTIF(Index!$D$2:$D$4903,"SPIE *") -> 55
A40: BioCAS | B40: =SUM(C40:M40) -> 2 | C40: 2 | O40: =COUNTIF(Index!$D$2:$D$4903,"BioCAS *") -> 4
...
